Workbook

Sheet вересень
A2: НАЦІОНАЛЬНИЙ УНІВЕРСИТЕТ ФІЗИЧНОГО ВИХОВАННЯ І СПОРТУ УКРАЇНИ
I4: "Затверджую"
H6: Завідувач кафедри ____________
A7: ЗВІТ
A8: про виконану роботу НПП кафедри ОЗДОРОВЧО-РЕКРЕАЦІЙНОЇ РУХОВОЇ АКТИВНОСТІ
A10: Хрипко Інни Василівни | K10: за вересень 2025 р.
D11: (прізвище, ім'я, по батькові)
A12: посада | C12: доцент | H12: розмір ставки | J12: 1
A14: 1. Навчальна робота
A15: Дата | B15: Час занять | C15: Група | D15: Лекції | E15: Практичні та лабораторні заняття | F15: Семінарські заняття | G15: Консультації до кваліфікаційних робіт та атестаційних екзаменів | H15: Консультації до курсових робіт | I15: Захист звіту з практичної підготовки | J15: Семестрові екзамени | K15: Атестація | L15: Практика | M15: Усього годин
A16: 10.09 | B16: 15.45 | C16: 55-СО | D16: 2 | M16: =SUM(D16:L16) -> 2
A17: 11.09 | B17: 14.00 | C17: 55-СО | D17: 2 | M17: =SUM(D17:L17) -> 2
A18: 11.09 | B18: 15.45 | C18: 55-СО | D18: 2 | M18: =SUM(D18:L18) -> 2
A19: 12.09 | B19: 15.45 | C19: 55-СО | D19: 2 | M19: =SUM(D19:L19) -> 2
A20: 15.09 | B20: 14.00 | C20: ФЗН3 курс | D20: 2 | M20: =SUM(D20:L20) -> 2
A21: 16.09 | B21: 14.00 | C21: ФЗН3 курс | D21: 2 | M21: =SUM(D21:L21) -> 2
A22: 17.09 | B22: 15.40 | C22: ФЗН3 курс | D22: 2 | M22: =SUM(D22:L22) -> 2
A23: 18.09 | B23: 15.40 | C23: ФЗН3 курс | D23: 2 | M23: =SUM(D23:L23) -> 2
A24: 25.09 | B24: 19.00 | C24: ДВ | E24: 2 | M24: =SUM(D24:L24) -> 2
A25: 26.09 | B25: 17.20 | C25: ДВ | E25: 2 | M25: =SUM(D25:L25) -> 2
A26: 29.09 | B26: 19.00 | C26: ДВ | E26: 2 | M26: =SUM(D26:L26) -> 2
M27: =SUM(D27:L27) -> 0
M28: =SUM(D28:L28) -> 0
M29: =SUM(D29:L29) -> 0
M30: =SUM(D30:L30) -> 0
M31: =SUM(D31:L31) -> 0
M32: =SUM(D32:L32) -> 0
M33: =SUM(D33:L33) -> 0
M34: =SUM(D34:L34) -> 0
M35: =SUM(D35:L35) -> 0
M36: =SUM(D36:L36) -> 0
M37: =SUM(D37:L37) -> 0
M38: =SUM(D38:L38) -> 0
... M46: =SUM(D46:L46) -> 0
A47: Усього за місяць | D47: =SUM(D16:D46) -> 16 | E47: =SUM(E16:E46) -> 6 | F47: =SUM(F16:F46) -> 0 | G47: =SUM(G16:G46) -> 0 | H47: =SUM(H16:H46) -> 0 | I47: =SUM(I16:I46) -> 0 | J47: =SUM(J16:J46) -> 0 | K47: =SUM(K16:K46) -> 0 | ... M47: =SUM(M16:M46) -> 22
A49: II. Методична робота
A50: № | B50: Види роботи | L50: Кількість годин
A51: 1 | B51: Підготовка до практичних | L51: 3
A52: 2 | B52: Оновлення змісту навчальних занять: лекцій, семінарських, лабораторних та практичних занять | L52: 10
A53: 3
...

Sheet жовтень
A2: НАЦІОНАЛЬНИЙ УНІВЕРСИТЕТ ФІЗИЧНОГО ВИХОВАННЯ І СПОРТУ УКРАЇНИ
I4: "Затверджую"
H6: Завідувач кафедри ____________
A7: ЗВІТ
A8: про виконану роботу НПП кафедри ОЗДОРОВЧО-РЕКРЕАЦІЙНОЇ РУХОВОЇ АКТИВНОСТІ
A10: Хрипко Інни Василівни | K10: за жовтень 2025 р.
D11: (прізвище, ім'я, по батькові)
A12: посада | C12: доцент | H12: розмір ставки | J12: 1
A14: 1. Навчальна робота
A15: Дата | B15: Час занять | C15: Група | D15: Лекції | E15: Практичні та лабораторні заняття | F15: Семінарські заняття | G15: Консультації до кваліфікаційних робіт та атестаційних екзаменів | H15: Консультації до курсових робіт | I15: Захист звіту з практичної підготовки | J15: Семестрові екзамени | K15: Атестація | L15: Практика | M15: Усього годин
A16: 8.10 | B16: 15.40 | C16: 45-СО | D16: 2 | M16: =SUM(D16:L16) -> 2
A17: 9.10 | B17: 15.40 | C17: 45-СО | D17: 2 | M17: =SUM(D17:L17) -> 2
A18: 9.10 | B18: 17.30 | C18: 15-ТД2 | E18: 2 | M18: =SUM(D18:L18) -> 2
A19: 10.10 | B19: 12.15 | C19: 45-ФР | D19: 2 | M19: =SUM(D19:L19) -> 2
A20: 11.10 | B20: 8.45 | C20: 45-ФР | E20: 2 | M20: =SUM(D20:L20) -> 2
A21: 11.10 | B21: 10.30 | C21: 15-ТД2 | E21: 2 | M21: =SUM(D21:L21) -> 2
A22: 23.10 | B22: 14.00 | C22: 55-СО | E22: 2 | M22: =SUM(D22:L22) -> 2
A23: 24.10 | B23: 14.00 | C23: 55-СО | E23: 2 | M23: =SUM(D23:L23) -> 2
A24: 25.10 | B24: 10.30 | C24: 55-СО | E24: 2 | M24: =SUM(D24:L24) -> 2
A25: 30.10 | B25: 15.45 | C25: 55-СО | E25: 2 | M25: =SUM(D25:L25) -> 2
M26: =SUM(D26:L26) -> 0
M27: =SUM(D27:L27) -> 0
M28: =SUM(D28:L28) -> 0
M29: =SUM(D29:L29) -> 0
M30: =SUM(D30:L30) -> 0
M31: =SUM(D31:L31) -> 0
M32: =SUM(D32:L32) -> 0
M33: =SUM(D33:L33) -> 0
M34: =SUM(D34:L34) -> 0
M35: =SUM(D35:L35) -> 0
M36: =SUM(D36:L36) -> 0
M37: =SUM(D37:L37) -> 0
... M46: =SUM(D46:L46) -> 0
A47: Усього за місяць | D47: =SUM(D16:D46) -> 6 | E47: =SUM(E16:E46) -> 14 | F47: =SUM(F16:F46) -> 0 | G47: =SUM(G16:G46) -> 0 | H47: =SUM(H16:H46) -> 0 | I47: =SUM(I16:I46) -> 0 | J47: =SUM(J16:J46) -> 0 | K47: =SUM(K16:K46) -> 0 | ... M47: =SUM(M16:M46) -> 20
A49: II. Методична робота
A50: № | B50: Види роботи
A51: 1 | B51: Підготовка до практичних | M51: 7
A52: 2 | B52: Оновлення змісту навчальних занять: лекцій, семінарських, лабораторних та практичних занять | M52: 15
A53: 3
A54: 4
...

Sheet листопад
A2: НАЦІОНАЛЬНИЙ УНІВЕРСИТЕТ ФІЗИЧНОГО ВИХОВАННЯ І СПОРТУ УКРАЇНИ
I4: "Затверджую"
H6: Завідувач кафедри ____________
A7: ЗВІТ
A8: про виконану роботу НПП кафедри ОЗДОРОВЧО-РЕКРЕАЦІЙНОЇ РУХОВОЇ АКТИВНОСТІ
A10: Хрипко Інни Василівни | K10: за листопад 2025 р.
D11: (прізвище, ім'я, по батькові)
A12: посада | C12: доцент | H12: розмір ставки | J12: 1
A14: 1. Навчальна робота
A15: Дата | B15: Час занять | C15: Група | D15: Лекції | E15: Практичні та лабораторні заняття | F15: Семінарські заняття | G15: Консультації до кваліфікаційних робіт та атестаційних екзаменів | H15: Консультації до курсових робіт | I15: Захист звіту з практичної підготовки | J15: Семестрові екзамени | K15: Атестація | L15: Практика | M15: Усього годин
A16: 4.11 | B16: 15.40 | C16: 35-ТД 1 | E16: 2 | M16: =SUM(D16:L16) -> 2
A17: 4.11 | B17: 17.20 | C17: 35-ТД 1 | E17: 2 | M17: =SUM(D17:L17) -> 2
A18: 5.11 | B18: 10.30 | C18: 35-ТД 2 | E18: 2 | M18: =SUM(D18:L18) -> 2
A19: 5.11 | B19: 12.15 | C19: 35-ТД 2 | E19: 2 | M19: =SUM(D19:L19) -> 2
A20: 5.11 | B20: 15.40 | C20: 35-ТД 4 | E20: 2 | M20: =SUM(D20:L20) -> 2
A21: 5.11 | B21: 17.20 | C21: 35-ФР | E21: 2 | M21: =SUM(D21:L21) -> 2
A22: 5.11 | B22: 19.00 | C22: 35-ТД 3 | E22: 2 | M22: =SUM(D22:L22) -> 2
A23: 6.11 | B23: 10.30 | C23: 35-ФВОС | E23: 2 | M23: =SUM(D23:L23) -> 2
A24: 6.11 | B24: 12.15 | C24: 35-МСД | E24: 2 | M24: =SUM(D24:L24) -> 2
A25: 6.11 | B25: 15.45 | C25: 35-ФСР | E25: 2 | M25: =SUM(D25:L25) -> 2
A26: 6.11 | B26: 17.20 | C26: 35-ТД 3 | E26: 2 | M26: =SUM(D26:L26) -> 2
A27: 6.11 | B27: 19.00 | C27: 35-ТД 4 | E27: 2 | M27: =SUM(D27:L27) -> 2
... A87: 29.11 | B87: 14.00 | C87: 45-ФР | E87: 2 | M87: =SUM(D87:L87) -> 2
M88: =SUM(D88:L88) -> 0
M89: =SUM(D89:L89) -> 0
A90: Усього за місяць | D90: =SUM(D16:D89) -> 0 | E90: =SUM(E16:E89) -> 144 | F90: =SUM(F16:F89) -> 0 | G90: =SUM(G16:G89) -> 0 | H90: =SUM(H16:H89) -> 0 | I90: =SUM(I16:I89) -> 0 | J90: =SUM(J16:J89) -> 0 | K90: =SUM(K16:K89) -> 0 | ... M90: =SUM(M16:M89) -> 144
A92: II. Методична робота
A93: № | B93: Види роботи
A94: 1 | B94: Підготовка до практичних занять | M94: 4
A95: 2
A96: 3
A97: 4
A98: 5
A99: 6
A100: 7
A101: 8
A102: 9
A103: 10
K104: Усього | M104: =SUM(M94:M103) -> 4
A105: III. Наукова робота
...

Sheet грудень
A2: НАЦІОНАЛЬНИЙ УНІВЕРСИТЕТ ФІЗИЧНОГО ВИХОВАННЯ І СПОРТУ УКРАЇНИ
I4: "Затверджую"
H6: Завідувач кафедри ____________
A7: ЗВІТ
A8: про виконану роботу НПП кафедри ОЗДОРОВЧО-РЕКРЕАЦІЙНОЇ РУХОВОЇ АКТИВНОСТІ
A10: Хрипко Інни Василівни | K10: за грудень 2025 р.
D11: (прізвище, ім'я, по батькові)
A12: посада | C12: доцент | H12: розмір ставки | J12: 1
A14: 1. Навчальна робота
A15: Дата | B15: Час занять | C15: Група | D15: Лекції | E15: Практичні та лабораторні заняття | F15: Семінарські заняття | G15: Консультації до кваліфікаційних робіт та атестаційних екзаменів | H15: Консультації до курсових робіт | I15: Захист звіту з практичної підготовки | J15: Семестрові екзамени | K15: Атестація | L15: Практика | M15: Усього годин
G16: 10 | M16: =SUM(D16:L16) -> 10
E17: 22 | M17: =SUM(D17:L17) -> 22
M18: =SUM(D18:L18) -> 0
M19: =SUM(D19:L19) -> 0
M20: =SUM(D20:L20) -> 0
M21: =SUM(D21:L21) -> 0
M22: =SUM(D22:L22) -> 0
M23: =SUM(D23:L23) -> 0
M24: =SUM(D24:L24) -> 0
M25: =SUM(D25:L25) -> 0
M26: =SUM(D26:L26) -> 0
M27: =SUM(D27:L27) -> 0
M28: =SUM(D28:L28) -> 0
M29: =SUM(D29:L29) -> 0
... M46: =SUM(D46:L46) -> 0
A47: Усього за місяць | D47: =SUM(D16:D46) -> 0 | E47: =SUM(E16:E46) -> 22 | F47: =SUM(F16:F46) -> 0 | G47: =SUM(G16:G46) -> 10 | H47: =SUM(H16:H46) -> 0 | I47: =SUM(I16:I46) -> 0 | J47: =SUM(J16:J46) -> 0 | K47: =SUM(K16:K46) -> 0 | ... M47: =SUM(M16:M46) -> 32
A49: II. Методична робота
A50: № | B50: Види роботи
A51: 1
A52: 2
A53: 3
A54: 4
A55: 5
A56: 6
A57: 7
A58: 8
A59: 9
A60: 10
K61: Усього | M61: =SUM(M51:M60) -> 0
A62: III. Наукова робота
...

Sheet січень
A2: НАЦІОНАЛЬНИЙ УНІВЕРСИТЕТ ФІЗИЧНОГО ВИХОВАННЯ І СПОРТУ УКРАЇНИ
I4: "Затверджую"
H6: Завідувач кафедри ____________
A7: ЗВІТ
A8: про виконану роботу НПП кафедри ОЗДОРОВЧО-РЕКРЕАЦІЙНОЇ РУХОВОЇ АКТИВНОСТІ
A10: Хрипко Інни Василівни | K10: за січень 2026 р.
D11: (прізвище, ім'я, по батькові)
A12: посада | C12: доцент | H12: розмір ставки | J12: 1
A14: 1. Навчальна робота
A15: Дата | B15: Час занять | C15: Група | D15: Лекції | E15: Практичні та лабораторні заняття | F15: Семінарські заняття | G15: Консультації до кваліфікаційних робіт та атестаційних екзаменів | H15: Консультації до курсових робіт | I15: Захист звіту з практичної підготовки | J15: Семестрові екзамени | K15: Атестація | L15: Практика | M15: Усього годин
M16: =SUM(D16:L16) -> 0
M17: =SUM(D17:L17) -> 0
M18: =SUM(D18:L18) -> 0
M19: =SUM(D19:L19) -> 0
M20: =SUM(D20:L20) -> 0
M21: =SUM(D21:L21) -> 0
M22: =SUM(D22:L22) -> 0
M23: =SUM(D23:L23) -> 0
M24: =SUM(D24:L24) -> 0
M25: =SUM(D25:L25) -> 0
M26: =SUM(D26:L26) -> 0
M27: =SUM(D27:L27) -> 0
... M46: =SUM(D46:L46) -> 0
A47: Усього за місяць | D47: =SUM(D16:D46) -> 0 | E47: =SUM(E16:E46) -> 0 | F47: =SUM(F16:F46) -> 0 | G47: =SUM(G16:G46) -> 0 | H47: =SUM(H16:H46) -> 0 | I47: =SUM(I16:I46) -> 0 | J47: =SUM(J16:J46) -> 0 | K47: =SUM(K16:K46) -> 0 | ... M47: =SUM(M16:M46) -> 0
A49: II. Методична робота
A50: № | B50: Види роботи
A51: 1
A52: 2
A53: 3
A54: 4
A55: 5
A56: 6
A57: 7
A58: 8
A59: 9
A60: 10
K61: Усього | M61: =SUM(M51:M60) -> 0
A62: III. Наукова робота
A63: № | B63: Види роботи
A64: 1
...

Sheet лютий
A2: НАЦІОНАЛЬНИЙ УНІВЕРСИТЕТ ФІЗИЧНОГО ВИХОВАННЯ І СПОРТУ УКРАЇНИ
I4: "Затверджую"
H6: Завідувач кафедри ____________
A7: ЗВІТ
A8: про виконану роботу НПП кафедри ОЗДОРОВЧО-РЕКРЕАЦІЙНОЇ РУХОВОЇ АКТИВНОСТІ
A10: Хрипко Інни Василівни | K10: за лютий 2026 р.
D11: (прізвище, ім'я, по батькові)
A12: посада | C12: доцент | H12: розмір ставки | J12: 1
A14: 1. Навчальна робота
A15: Дата | B15: Час занять | C15: Група | D15: Лекції | E15: Практичні та лабораторні заняття | F15: Семінарські заняття | G15: Консультації до кваліфікаційних робіт та атестаційних екзаменів | H15: Консультації до курсових робіт | I15: Захист звіту з практичної підготовки | J15: Семестрові екзамени | K15: Атестація | L15: Практика | M15: Усього годин
M16: =SUM(D16:L16) -> 0
M17: =SUM(D17:L17) -> 0
M18: =SUM(D18:L18) -> 0
M19: =SUM(D19:L19) -> 0
M20: =SUM(D20:L20) -> 0
M21: =SUM(D21:L21) -> 0
M22: =SUM(D22:L22) -> 0
M23: =SUM(D23:L23) -> 0
M24: =SUM(D24:L24) -> 0
M25: =SUM(D25:L25) -> 0
M26: =SUM(D26:L26) -> 0
M27: =SUM(D27:L27) -> 0
... M46: =SUM(D46:L46) -> 0
A47: Усього за місяць | D47: =SUM(D16:D46) -> 0 | E47: =SUM(E16:E46) -> 0 | F47: =SUM(F16:F46) -> 0 | G47: =SUM(G16:G46) -> 0 | H47: =SUM(H16:H46) -> 0 | I47: =SUM(I16:I46) -> 0 | J47: =SUM(J16:J46) -> 0 | K47: =SUM(K16:K46) -> 0 | ... M47: =SUM(M16:M46) -> 0
A49: II. Методична робота
A50: № | B50: Види роботи
A51: 1
A52: 2
A53: 3
A54: 4
A55: 5
A56: 6
A57: 7
A58: 8
A59: 9
A60: 10
K61: Усього | M61: =SUM(M51:M60) -> 0
A62: III. Наукова робота
A63: № | B63: Види роботи
A64: 1
...

Sheet березень
A2: НАЦІОНАЛЬНИЙ УНІВЕРСИТЕТ ФІЗИЧНОГО ВИХОВАННЯ І СПОРТУ УКРАЇНИ
I4: "Затверджую"
H6: Завідувач кафедри ____________
A7: ЗВІТ
A8: про виконану роботу НПП кафедри ОЗДОРОВЧО-РЕКРЕАЦІЙНОЇ РУХОВОЇ АКТИВНОСТІ
A10: Хрипко Інни Василівни | K10: за березень 2026 р.
D11: (прізвище, ім'я, по батькові)
A12: посада | C12: доцент | H12: розмір ставки | J12: 1
A14: 1. Навчальна робота
A15: Дата | B15: Час занять | C15: Група | D15: Лекції | E15: Практичні та лабораторні заняття | F15: Семінарські заняття | G15: Консультації до кваліфікаційних робіт та атестаційних екзаменів | H15: Консультації до курсових робіт | I15: Захист звіту з практичної підготовки | J15: Семестрові екзамени | K15: Атестація | L15: Практика | M15: Усього годин
M16: =SUM(D16:L16) -> 0
M17: =SUM(D17:L17) -> 0
M18: =SUM(D18:L18) -> 0
M19: =SUM(D19:L19) -> 0
M20: =SUM(D20:L20) -> 0
M21: =SUM(D21:L21) -> 0
M22: =SUM(D22:L22) -> 0
M23: =SUM(D23:L23) -> 0
M24: =SUM(D24:L24) -> 0
M25: =SUM(D25:L25) -> 0
M26: =SUM(D26:L26) -> 0
M27: =SUM(D27:L27) -> 0
... M46: =SUM(D46:L46) -> 0
A47: Усього за місяць | D47: =SUM(D16:D46) -> 0 | E47: =SUM(E16:E46) -> 0 | F47: =SUM(F16:F46) -> 0 | G47: =SUM(G16:G46) -> 0 | H47: =SUM(H16:H46) -> 0 | I47: =SUM(I16:I46) -> 0 | J47: =SUM(J16:J46) -> 0 | K47: =SUM(K16:K46) -> 0 | ... M47: =SUM(M16:M46) -> 0
A49: II. Методична робота
A50: № | B50: Види роботи
A51: 1
A52: 2
A53: 3
A54: 4
A55: 5
A56: 6
A57: 7
A58: 8
A59: 9
A60: 10
K61: Усього | M61: =SUM(M51:M60) -> 0
A62: III. Наукова робота
A63: № | B63: Види роботи
A64: 1
...

Sheet квітень
A2: НАЦІОНАЛЬНИЙ УНІВЕРСИТЕТ ФІЗИЧНОГО ВИХОВАННЯ І СПОРТУ УКРАЇНИ
I4: "Затверджую"
H6: Завідувач кафедри ____________
A7: ЗВІТ
A8: про виконану роботу НПП кафедри ОЗДОРОВЧО-РЕКРЕАЦІЙНОЇ РУХОВОЇ АКТИВНОСТІ
A10: Хрипко Інни Василівни | K10: за квітень 2026 р.
D11: (прізвище, ім'я, по батькові)
A12: посада | C12: доцент | H12: розмір ставки | J12: 1
A14: 1. Навчальна робота
A15: Дата | B15: Час занять | C15: Група | D15: Лекції | E15: Практичні та лабораторні заняття | F15: Семінарські заняття | G15: Консультації до кваліфікаційних робіт та атестаційних екзаменів | H15: Консультації до курсових робіт | I15: Захист звіту з практичної підготовки | J15: Семестрові екзамени | K15: Атестація | L15: Практика | M15: Усього годин
M16: =SUM(D16:L16) -> 0
M17: =SUM(D17:L17) -> 0
M18: =SUM(D18:L18) -> 0
M19: =SUM(D19:L19) -> 0
M20: =SUM(D20:L20) -> 0
M21: =SUM(D21:L21) -> 0
M22: =SUM(D22:L22) -> 0
M23: =SUM(D23:L23) -> 0
M24: =SUM(D24:L24) -> 0
M25: =SUM(D25:L25) -> 0
M26: =SUM(D26:L26) -> 0
M27: =SUM(D27:L27) -> 0
... M46: =SUM(D46:L46) -> 0
A47: Усього за місяць | D47: =SUM(D16:D46) -> 0 | E47: =SUM(E16:E46) -> 0 | F47: =SUM(F16:F46) -> 0 | G47: =SUM(G16:G46) -> 0 | H47: =SUM(H16:H46) -> 0 | I47: =SUM(I16:I46) -> 0 | J47: =SUM(J16:J46) -> 0 | K47: =SUM(K16:K46) -> 0 | ... M47: =SUM(M16:M46) -> 0
A49: II. Методична робота
A50: № | B50: Види роботи
A51: 1
A52: 2
A53: 3
A54: 4
A55: 5
A56: 6
A57: 7
A58: 8
A59: 9
A60: 10
K61: Усього | M61: =SUM(M51:M60) -> 0
A62: III. Наукова робота
A63: № | B63: Види роботи
A64: 1
...

Sheet травень
A2: НАЦІОНАЛЬНИЙ УНІВЕРСИТЕТ ФІЗИЧНОГО ВИХОВАННЯ І СПОРТУ УКРАЇНИ
I4: "Затверджую"
H6: Завідувач кафедри ____________
A7: ЗВІТ
A8: про виконану роботу НПП кафедри ОЗДОРОВЧО-РЕКРЕАЦІЙНОЇ РУХОВОЇ АКТИВНОСТІ
A10: Хрипко Інни Василівни | K10: за травень 2026 р.
D11: (прізвище, ім'я, по батькові)
A12: посада | C12: доцент | H12: розмір ставки | J12: 1
A14: 1. Навчальна робота
A15: Дата | B15: Час занять | C15: Група | D15: Лекції | E15: Практичні та лабораторні заняття | F15: Семінарські заняття | G15: Консультації до кваліфікаційних робіт та атестаційних екзаменів | H15: Консультації до курсових робіт | I15: Захист звіту з практичної підготовки | J15: Семестрові екзамени | K15: Атестація | L15: Практика | M15: Усього годин
M16: =SUM(D16:L16) -> 0
M17: =SUM(D17:L17) -> 0
M18: =SUM(D18:L18) -> 0
M19: =SUM(D19:L19) -> 0
M20: =SUM(D20:L20) -> 0
M21: =SUM(D21:L21) -> 0
M22: =SUM(D22:L22) -> 0
M23: =SUM(D23:L23) -> 0
M24: =SUM(D24:L24) -> 0
M25: =SUM(D25:L25) -> 0
M26: =SUM(D26:L26) -> 0
M27: =SUM(D27:L27) -> 0
... M46: =SUM(D46:L46) -> 0
A47: Усього за місяць | D47: =SUM(D16:D46) -> 0 | E47: =SUM(E16:E46) -> 0 | F47: =SUM(F16:F46) -> 0 | G47: =SUM(G16:G46) -> 0 | H47: =SUM(H16:H46) -> 0 | I47: =SUM(I16:I46) -> 0 | J47: =SUM(J16:J46) -> 0 | K47: =SUM(K16:K46) -> 0 | ... M47: =SUM(M16:M46) -> 0
A49: II. Методична робота
A50: № | B50: Види роботи
A51: 1
A52: 2
A53: 3
A54: 4
A55: 5
A56: 6
A57: 7
A58: 8
A59: 9
A60: 10
K61: Усього | M61: =SUM(M51:M60) -> 0
A62: III. Наукова робота
A63: № | B63: Види роботи
A64: 1
...

Sheet червень
A2: НАЦІОНАЛЬНИЙ УНІВЕРСИТЕТ ФІЗИЧНОГО ВИХОВАННЯ І СПОРТУ УКРАЇНИ
I4: "Затверджую"
H6: Завідувач кафедри ____________
A7: ЗВІТ
A8: про виконану роботу НПП кафедри ОЗДОРОВЧО-РЕКРЕАЦІЙНОЇ РУХОВОЇ АКТИВНОСТІ
A10: Хрипко Інни Василівни | K10: за червень 2026 р.
D11: (прізвище, ім'я, по батькові)
A12: посада | C12: доцент | H12: розмір ставки | J12: 1
A14: 1. Навчальна робота
A15: Дата | B15: Час занять | C15: Група | D15: Лекції | E15: Практичні та лабораторні заняття | F15: Семінарські заняття | G15: Консультації до кваліфікаційних робіт та атестаційних екзаменів | H15: Консультації до курсових робіт | I15: Захист звіту з практичної підготовки | J15: Семестрові екзамени | K15: Атестація | L15: Практика | M15: Усього годин
M16: =SUM(D16:L16) -> 0
M17: =SUM(D17:L17) -> 0
M18: =SUM(D18:L18) -> 0
M19: =SUM(D19:L19) -> 0
M20: =SUM(D20:L20) -> 0
M21: =SUM(D21:L21) -> 0
M22: =SUM(D22:L22) -> 0
M23: =SUM(D23:L23) -> 0
M24: =SUM(D24:L24) -> 0
M25: =SUM(D25:L25) -> 0
M26: =SUM(D26:L26) -> 0
M27: =SUM(D27:L27) -> 0
... M46: =SUM(D46:L46) -> 0
A47: Усього за місяць | D47: =SUM(D16:D46) -> 0 | E47: =SUM(E16:E46) -> 0 | F47: =SUM(F16:F46) -> 0 | G47: =SUM(G16:G46) -> 0 | H47: =SUM(H16:H46) -> 0 | I47: =SUM(I16:I46) -> 0 | J47: =SUM(J16:J46) -> 0 | K47: =SUM(K16:K46) -> 0 | ... M47: =SUM(M16:M46) -> 0
A49: II. Методична робота
A50: № | B50: Види роботи
A51: 1
A52: 2
A53: 3
A54: 4
A55: 5
A56: 6
A57: 7
A58: 8
A59: 9
A60: 10
K61: Усього | M61: =SUM(M51:M60) -> 0
A62: III. Наукова робота
A63: № | B63: Види роботи
A64: 1
...

Sheet липень
A2: НАЦІОНАЛЬНИЙ УНІВЕРСИТЕТ ФІЗИЧНОГО ВИХОВАННЯ І СПОРТУ УКРАЇНИ
I4: "Затверджую"
H6: Завідувач кафедри ____________
A7: ЗВІТ
A8: про виконану роботу НПП кафедри ОЗДОРОВЧО-РЕКРЕАЦІЙНОЇ РУХОВОЇ АКТИВНОСТІ
A10: Хрипко Інни Василівни | K10: за липень 2026 р.
D11: (прізвище, ім'я, по батькові)
A12: посада | C12: доцент | H12: розмір ставки | J12: 1
A14: 1. Навчальна робота
A15: Дата | B15: Час занять | C15: Група | D15: Лекції | E15: Практичні та лабораторні заняття | F15: Семінарські заняття | G15: Консультації до кваліфікаційних робіт та атестаційних екзаменів | H15: Консультації до курсових робіт | I15: Захист звіту з практичної підготовки | J15: Семестрові екзамени | K15: Атестація | L15: Практика | M15: Усього годин
M16: =SUM(D16:L16) -> 0
M17: =SUM(D17:L17) -> 0
M18: =SUM(D18:L18) -> 0
M19: =SUM(D19:L19) -> 0
M20: =SUM(D20:L20) -> 0
M21: =SUM(D21:L21) -> 0
M22: =SUM(D22:L22) -> 0
M23: =SUM(D23:L23) -> 0
M24: =SUM(D24:L24) -> 0
M25: =SUM(D25:L25) -> 0
M26: =SUM(D26:L26) -> 0
M27: =SUM(D27:L27) -> 0
... M46: =SUM(D46:L46) -> 0
A47: Усього за місяць | D47: =SUM(D16:D46) -> 0 | E47: =SUM(E16:E46) -> 0 | F47: =SUM(F16:F46) -> 0 | G47: =SUM(G16:G46) -> 0 | H47: =SUM(H16:H46) -> 0 | I47: =SUM(I16:I46) -> 0 | J47: =SUM(J16:J46) -> 0 | K47: =SUM(K16:K46) -> 0 | ... M47: =SUM(M16:M46) -> 0
A49: II. Методична робота
A50: № | B50: Види роботи
A51: 1
A52: 2
A53: 3
A54: 4
A55: 5
A56: 6
A57: 7
A58: 8
A59: 9
A60: 10
K61: Усього | M61: =SUM(M51:M60) -> 0
A62: III. Наукова робота
A63: № | B63: Види роботи
A64: 1
...

Sheet серпень
A2: НАЦІОНАЛЬНИЙ УНІВЕРСИТЕТ ФІЗИЧНОГО ВИХОВАННЯ І СПОРТУ УКРАЇНИ
I4: "Затверджую"
H6: Завідувач кафедри ____________
A7: ЗВІТ
A8: про виконану роботу НПП кафедри ОЗДОРОВЧО-РЕКРЕАЦІЙНОЇ РУХОВОЇ АКТИВНОСТІ
A10: Хрипко Інни Василівни | K10: за серпень 2026 р.
D11: (прізвище, ім'я, по батькові)
A12: посада | C12: доцент | H12: розмір ставки | J12: 1
A14: 1. Навчальна робота
A15: Дата | B15: Час занять | C15: Група | D15: Лекції | E15: Практичні та лабораторні заняття | F15: Семінарські заняття | G15: Консультації до кваліфікаційних робіт та атестаційних екзаменів | H15: Консультації до курсових робіт | I15: Захист звіту з практичної підготовки | J15: Семестрові екзамени | K15: Атестація | L15: Практика | M15: Усього годин
M16: =SUM(D16:L16) -> 0
M17: =SUM(D17:L17) -> 0
M18: =SUM(D18:L18) -> 0
M19: =SUM(D19:L19) -> 0
M20: =SUM(D20:L20) -> 0
M21: =SUM(D21:L21) -> 0
M22: =SUM(D22:L22) -> 0
M23: =SUM(D23:L23) -> 0
M24: =SUM(D24:L24) -> 0
M25: =SUM(D25:L25) -> 0
M26: =SUM(D26:L26) -> 0
M27: =SUM(D27:L27) -> 0
... M46: =SUM(D46:L46) -> 0
A47: Усього за місяць | D47: =SUM(D16:D46) -> 0 | E47: =SUM(E16:E46) -> 0 | F47: =SUM(F16:F46) -> 0 | G47: =SUM(G16:G46) -> 0 | H47: =SUM(H16:H46) -> 0 | I47: =SUM(I16:I46) -> 0 | J47: =SUM(J16:J46) -> 0 | K47: =SUM(K16:K46) -> 0 | ... M47: =SUM(M16:M46) -> 0
A49: II. Методична робота
A50: № | B50: Види роботи
A51: 1
A52: 2
A53: 3
A54: 4
A55: 5
A56: 6
A57: 7
A58: 8
A59: 9
A60: 10
K61: Усього | M61: =SUM(M51:M60) -> 0
A62: III. Наукова робота
A63: № | B63: Види роботи
A64: 1
...

Sheet ЗВІТ
B1: ЗВІТ
B2: Лекції | C2: Практичні та лабораторні заняття | D2: Семінарські заняття | E2: Консультації до кваліфікаційних робіт та атестаційних екзаменів | F2: Консультації до курсових робіт | G2: Захист звіту з практичної підготовки | H2: Семестрові екзамени | I2: Атестація | J2: Практика | K2: Усього годин | L2: МЕТОДИЧНА | M2: НАУКОВА | N2: ОРГАНІЗАЦІЙНА | O2: ВСЬОГО
A3: вересень | B3: =вересень!D47 -> 16 | C3: =вересень!E47 -> 6 | D3: =вересень!F47 -> 0 | E3: =вересень!G47 -> 0 | F3: =вересень!H47 -> 0 | G3: =вересень!I47 -> 0 | H3: =вересень!J47 -> 0 | I3: =вересень!K47 -> 0 | ... K3: =вересень!M47 -> 22 | L3: =вересень!L61 -> 13 | M3: =вересень!L74 -> 115 | N3: =вересень!L87 -> 6 | O3: =N3+M3+L3+K3 -> 156
A4: жовтень | B4: =жовтень!D47 -> 6 | C4: =жовтень!E47 -> 14 | D4: =жовтень!F47 -> 0 | E4: =жовтень!G47 -> 0 | F4: =жовтень!H47 -> 0 | G4: =жовтень!I47 -> 0 | H4: =жовтень!J47 -> 0 | I4: =жовтень!K47 -> 0 | ... K4: =жовтень!M47 -> 20 | L4: =жовтень!M61 -> 22 | M4: =жовтень!M74 -> 117 | N4: =жовтень!M87 -> 6 | O4: =N4+M4+L4+K4 -> 165
A5: листопад | B5: =листопад!D90 -> 0 | C5: =листопад!E90 -> 144 | D5: =листопад!F90 -> 0 | E5: =листопад!G90 -> 0 | F5: =листопад!H90 -> 0 | G5: =листопад!I90 -> 0 | H5: =листопад!J90 -> 0 | I5: =листопад!K90 -> 0 | ... K5: =листопад!M90 -> 144 | L5: =листопад!M104 -> 4 | M5: =листопад!M117 -> 0 | N5: =листопад!M130 -> 2 | O5: =N5+M5+L5+K5 -> 150
A6: грудень | B6: =грудень!D47 -> 0 | C6: =грудень!E47 -> 22 | D6: =грудень!F47 -> 0 | E6: =грудень!G47 -> 10 | F6: =грудень!H47 -> 0 | G6: =грудень!I47 -> 0 | H6: =грудень!J47 -> 0 | I6: =грудень!K47 -> 0 | ... K6: =грудень!M47 -> 32 | L6: =грудень!M61 -> 0 | M6: =грудень!M74 -> 0 | N6: =грудень!M87 -> 0 | O6: =N6+M6+L6+K6 -> 32
A7: 1 семестр | B7: =SUM(B3:B6) -> 22 | C7: =SUM(C3:C6) -> 186 | D7: =SUM(D3:D6) -> 0 | E7: =SUM(E3:E6) -> 10 | F7: =SUM(F3:F6) -> 0 | G7: =SUM(G3:G6) -> 0 | H7: =SUM(H3:H6) -> 0 | I7: =SUM(I3:I6) -> 0 | ... O7: =SUM(O3:O6) -> 503
A8: січень | B8: =січень!D47 -> 0 | C8: =січень!E47 -> 0 | D8: =січень!F47 -> 0 | E8: =січень!G47 -> 0 | F8: =січень!H47 -> 0 | G8: =січень!I47 -> 0 | H8: =січень!J47 -> 0 | I8: =січень!K47 -> 0 | ... K8: =січень!M47 -> 0 | L8: =січень!M61 -> 0 | M8: =січень!M74 -> 0 | N8: =січень!M87 -> 0 | O8: =N8+M8+L8+K8 -> 0
A9: лютий | B9: =лютий!D47 -> 0 | C9: =лютий!E47 -> 0 | D9: =лютий!F47 -> 0 | E9: =лютий!G47 -> 0 | F9: =лютий!H47 -> 0 | G9: =лютий!I47 -> 0 | H9: =лютий!J47 -> 0 | I9: =лютий!K47 -> 0 | ... K9: =лютий!M47 -> 0 | L9: =лютий!M61 -> 0 | M9: =лютий!M74 -> 0 | N9: =лютий!M87 -> 0 | O9: =N9+M9+L9+K9 -> 0
A10: березень | B10: =березень!D47 -> 0 | C10: =березень!E47 -> 0 | D10: =березень!F47 -> 0 | E10: =березень!G47 -> 0 | F10: =березень!H47 -> 0 | G10: =березень!I47 -> 0 | H10: =березень!J47 -> 0 | I10: =березень!K47 -> 0 | ... K10: =березень!M47 -> 0 | L10: =березень!M61 -> 0 | M10: =березень!M74 -> 0 | N10: =березень!M87 -> 0 | O10: =N10+M10+L10+K10 -> 0
A11: квітень | B11: =квітень!D47 -> 0 | C11: =квітень!E47 -> 0 | D11: =квітень!F47 -> 0 | E11: =квітень!G47 -> 0 | F11: =квітень!H47 -> 0 | G11: =квітень!I47 -> 0 | H11: =квітень!J47 -> 0 | I11: =квітень!K47 -> 0 | ... K11: =квітень!M47 -> 0 | L11: =квітень!M61 -> 0 | M11: =квітень!M74 -> 0 | N11: =квітень!M87 -> 0 | O11: =N11+M11+L11+K11 -> 0
A12: травень | B12: =травень!D47 -> 0 | C12: =травень!E47 -> 0 | D12: =травень!F47 -> 0 | E12: =травень!G47 -> 0 | F12: =травень!H47 -> 0 | G12: =травень!I47 -> 0 | H12: =травень!J47 -> 0 | I12: =травень!K47 -> 0 | ... K12: =травень!M47 -> 0 | L12: =травень!M61 -> 0 | M12: =травень!M74 -> 0 | N12: =травень!M87 -> 0 | O12: =N12+M12+L12+K12 -> 0
A13: червень | B13: =червень!D47 -> 0 | C13: =червень!E47 -> 0 | D13: =червень!F47 -> 0 | E13: =червень!G47 -> 0 | F13: =червень!H47 -> 0 | G13: =червень!I47 -> 0 | H13: =червень!J47 -> 0 | I13: =червень!K47 -> 0 | ... K13: =червень!M47 -> 0 | L13: =червень!M61 -> 0 | M13: =червень!M74 -> 0 | N13: =червень!M87 -> 0 | O13: =N13+M13+L13+K13 -> 0
A14: липень | B14: =липень!D47 -> 0 | C14: =липень!E47 -> 0 | D14: =липень!F47 -> 0 | E14: =липень!G47 -> 0 | F14: =липень!H47 -> 0 | G14: =липень!I47 -> 0 | H14: =липень!J47 -> 0 | I14: =липень!K47 -> 0 | ... K14: =липень!M47 -> 0 | L14: =липень!M61 -> 0 | M14: =липень!M74 -> 0 | N14: =липень!M87 -> 0 | O14: =N14+M14+L14+K14 -> 0
A15: серпень | B15: =серпень!D47 -> 0 | C15: =серпень!E47 -> 0 | D15: =серпень!F47 -> 0 | E15: =серпень!G47 -> 0 | F15: =серпень!H47 -> 0 | G15: =серпень!I47 -> 0 | H15: =серпень!J47 -> 0 | I15: =серпень!K47 -> 0 | ... K15: =серпень!M47 -> 0 | L15: =серпень!M61 -> 0 | M15: =серпень!M74 -> 0 | N15: =серпень!M87 -> 0 | O15: =N15+M15+L15+K15 -> 0
A16: 2 семестр | B16: =SUM(B8:B15) -> 0 | C16: =SUM(C8:C15) -> 0 | D16: =SUM(D8:D15) -> 0 | E16: =SUM(E8:E15) -> 0 | F16: =SUM(F8:F15) -> 0 | G16: =SUM(G8:G15) -> 0 | H16: =SUM(H8:H15) -> 0 | I16: =SUM(I8:I15) -> 0 | ... O16: =SUM(O8:O15) -> 0
A17: ВСЬОГО | B17: =B16+B7 -> 22 | C17: =C16+C7 -> 186 | D17: =D16+D7 -> 0 | E17: =E16+E7 -> 10 | F17: =F16+F7 -> 0 | G17: =G16+G7 -> 0 | H17: =H16+H7 -> 0 | I17: =I16+I7 -> 0 | ... O17: =O16+O7 -> 503
